Workbook
Name Slicer_Discount_category: #N/A
Name Slicer_Product: #N/A
Name Slicer_Rating: #N/A
Name Slicer_Rating_category: #N/A

Sheet Dashboard
F9: Top Products with the highest ratings | I9: Top Products With the highest Reviews | L9: Top Product with the highest Discounts
F10: Product | G10: Rating | I10: Product | J10: Reviews | L10: Product | M10: Discount
F11: =Sheet9!A4 -> Anti-Skid Absorbent Insulation Coaster For Home Office | G11: =Sheet9!B4 -> 5 | I11: =Sheet10!E5 -> 120W Cordless Vacuum Cleaners Handheld Electric Vacuum Cleaner | J11: =Sheet10!F5 -> 69 | L11: =Sheet11!D5 -> 6 In 1 Bottle Can Opener Multifunctional Easy Opener | M11: =Sheet11!E5 -> 0.64
F12: =Sheet9!A5 -> Bedroom Simple Floor Hanging Clothes Rack Single Pole Hat Rack - White | G12: =Sheet9!B5 -> 5 | I12: =Sheet10!E6 -> 137 Pieces Cake Decorating Tool Set Baking Supplies | J12: =Sheet10!F6 -> 55 | L12: =Sheet11!D6 -> Creative Owl Shape Keychain Black | M12: =Sheet11!E6 -> 0.61
F13: =Sheet9!A6 -> Classic Black Cat Cotton Hemp Pillow Case For Home Car | G13: =Sheet9!B6 -> 5 | I13: =Sheet10!E9 -> Electronic Digital Display Vernier Caliper | J13: =Sheet10!F9 -> 49 | L13: =Sheet11!D4 -> 5-PCS Stainless Steel Cooking Pot Set With Steamed Slices | M13: =Sheet11!E4 -> 0.55
F14: =Sheet9!A7 -> DIY File Folder, Office Drawer File Holder, Pen Holder, Desktop Storage Rack | G14: =Sheet9!B7 -> 5 | I14: =Sheet10!E7 -> 3D Waterproof EVA Plastic Shower Curtain 1.8*2Mtrs | J14: =Sheet10!F7 -> 44 | L14: =Sheet11!D8 -> LASA FOLDING TABLE SERVING STAND | M14: =Sheet11!E8 -> 0.55
F15: =Sheet9!A8 -> Konka Healty Electric Kettle, 24-hour Heat Preservation,1.5L,800W, White | G15: =Sheet9!B8 -> 5 | I15: =Sheet10!E4 -> 100 Pcs Crochet Hook Tool Set Knitting Hook Set With Box | J15: =Sheet10!F4 -> 39 | L15: =Sheet11!D10 -> Simple Metal Dog Art Sculpture Decoration For Home Office | M15: =Sheet11!E10 -> 0.55
F16: =Sheet9!A9 -> LASA Aluminum Folding Truck Hand Cart - 68kg Max | G16: =Sheet9!B9 -> 5 | I16: =Sheet10!E10 -> Punch-free Great Load Bearing Bathroom Storage Rack Wall Shelf-White | J16: =Sheet10!F10 -> 36 | L16: =Sheet11!D7 -> LASA 3 Tier Bamboo Shoe Bench Storage Shelf | M16: =Sheet11!E7 -> 0.54
F17: =Sheet9!A10 -> Peacock Throw Pillow Cushion Case For Home Car | G17: =Sheet9!B10 -> 5 | I17: =Sheet10!E8 -> 53 Pieces/Set Yarn Knitting Crochet Hooks With Bag - Pansies | J17: =Sheet10!F8 -> 32 | L17: =Sheet11!D9 -> Mythco 120COB Solar Wall Ligt With Motion Sensor And Remote Control 3 Modes | M17: =Sheet11!E9 -> 0.54
F18: =Sheet9!A11 -> Grand Total | G18: =Sheet9!B11 -> 35 | I18: =Sheet10!E11 -> Grand Total | J18: =Sheet10!F11 -> 324 | L18: =Sheet11!D11 -> Grand Total | M18: =Sheet11!E11 -> 1

Sheet Sheet1
A1: Total No Of Product | B1: =COUNTA(Excel_jumia!A2:A113) -> 112
A2: Average Rating | B2: =ROUND(AVERAGE(Excel_jumia!G2:G113),2) -> 3.89
A3: Average Discount % | B3: =AVERAGE(Excel_jumia!E2:E113) -> 0.36776786
A4: Total No Of Reviews | B4: =SUM(Excel_jumia!F2:F113) -> 723

Sheet Sheet2
A1: Rating | B1: (All)
A3: Row Labels | B3: Sum of Rating
A4: 1/2/3 Seater Elastic Sofa Cover,Living Room/Home Decor Chair Cover-Grey | B4: 4.5
A5: 100 Pcs Crochet Hook Tool Set Knitting Hook Set With Box | B5: 4.7
A6: 115 Piece Set Of Multifunctional Precision Screwdrivers | B6: 4.5
A7: 12 Litre Black Insulated Lunch Box | B7: 3.8
A8: 12 Litre Insulated Lunch Box Grey | B8: 4.7
A9: 120W Cordless Vacuum Cleaners Handheld Electric Vacuum Cleaner | B9: 2.8
A10: 12V 19500rpm Handheld Electric Angle Grinder Tool - UK - Yellow/Black
A11: 13 In 1 Home Repair Tools Box Kit Set | B11: 3.8
A12: 137 Pieces Cake Decorating Tool Set Baking Supplies | B12: 4.6
A13: 1PC Refrigerator Food Seal Pocket Fridge Bags
A14: 2 Pairs Cowhide Split Leather Work Gloves.32â„‰ Or Above Welding Gloves
A15: 220V 60W Electric Soldering Iron Kits With Tools, Tips, And Multimeter | B15: 4
A16: 24 Grid Wall-mounted Sundries Organiser Fabric Closet Bag Storage Rack
A17: 2PCS Ice Silk Square Cushion Cover Pillowcases - 65x65cm
A18: 2pcs Solar Street Light Flood Light Outdoor
A19: 2PCS/LOT Solar LED Outdoor Intelligent Light Controlled Wall Lamp
A20: 32PCS Portable Cordless Drill Set With Cyclic Battery Drive -26 Variable Speed | B20: 3
A21: 380ML USB Rechargeable Portable Small Blenders And Juicers | B21: 2.3
A22: 3D Waterproof EVA Plastic Shower Curtain 1.8*2Mtrs | B22: 4.6
A23: 3PCS Rotary Scraper Thermomix For Kitchen
A24: 3PCS Single Head Knitting Crochet Sweater Needle Set | B24: 3.3
A25: 4 Piece Coloured Stainless Steel Kitchenware Set
A26: 40cm Gold DIY Acrylic Wall Sticker Clock | B26: 4.8
A27: 4M Float Switch Water Level Controller -Water Tank
A28: 4pcs Bathroom/Kitchen Towel Rack,Roll Paper Holder,Towel Bars,Hook
A29: 5 Pieces/set Of Stainless Steel Induction Cooker Pots | B29: 2.5
A30: 52 Pieces Cake Decorating Tool Set Gift Kit Baking Supplies | B30: 4.1
A31: 53 Pieces/Set Yarn Knitting Crochet Hooks With Bag - Pansies | B31: 4.5
A32: 53Pcs/Set Yarn Knitting Crochet Hooks With Bag - Fortune Cat | B32: 4.7
A33: 5m Waterproof Spherical LED String Lights Outdoor Ball Chain Lights Party Lighting Decoration Adjustable
A34: 5-PCS Stainless Steel Cooking Pot Set With Steamed Slices | B34: 2.1
A35: 6 In 1 Bottle Can Opener Multifunctional Easy Opener
A36: 6 Layers Steel Pipe Assembling Dustproof Storage Shoe Cabinet
A37: 60W Hot Melt Glue Sprayer - Efficient And Stable Glue Dispensing
A38: 7PCS Silicone Thumb Knife Finger Protector Vegetable Harvesting Knife
A39: 7-piece Set Of Storage Bags, Travel Storage Bags, Shoe Bags | B39: 2.2
A40: 8in1 Screwdriver With LED Light
A41: 9pcs Gas Mask, For Painting, Dust, Formaldehyde Grinding, Polishing
...

Sheet Sheet9
A1: Rating | B1: 5
A3: Product | B3: Rating | C3: No Of Reviews
A4: Anti-Skid Absorbent Insulation Coaster For Home Office | B4: 5 | C4: 2
A5: Bedroom Simple Floor Hanging Clothes Rack Single Pole Hat Rack - White | B5: 5 | C5: 1
A6: Classic Black Cat Cotton Hemp Pillow Case For Home Car | B6: 5 | C6: 2
A7: DIY File Folder, Office Drawer File Holder, Pen Holder, Desktop Storage Rack | B7: 5 | C7: 1
A8: Konka Healty Electric Kettle, 24-hour Heat Preservation,1.5L,800W, White | B8: 5 | C8: 1
A9: LASA Aluminum Folding Truck Hand Cart - 68kg Max | B9: 5 | C9: 3
A10: Peacock Throw Pillow Cushion Case For Home Car | B10: 5 | C10: 2
A11: Grand Total | B11: 35 | C11: 12
G12: =A4 -> Anti-Skid Absorbent Insulation Coaster For Home Office | H12: =B4 -> 5 | I12: =C4 -> 2
G13: =A5 -> Bedroom Simple Floor Hanging Clothes Rack Single Pole Hat Rack - White
G14: =A6 -> Classic Black Cat Cotton Hemp Pillow Case For Home Car
G15: =A7 -> DIY File Folder, Office Drawer File Holder, Pen Holder, Desktop Storage Rack
G16: =A8 -> Konka Healty Electric Kettle, 24-hour Heat Preservation,1.5L,800W, White
G17: =A9 -> LASA Aluminum Folding Truck Hand Cart - 68kg Max
G18: =A10 -> Peacock Throw Pillow Cushion Case For Home Car
G19: =A11 -> Grand Total

Sheet Sheet10
A1: Review | B1: (Multiple Items)
A3: Products | B3: No of Review
A4: 100 Pcs Crochet Hook Tool Set Knitting Hook Set With Box | B4: 39 | E4: =A4 -> 100 Pcs Crochet Hook Tool Set Knitting Hook Set With Box | F4: =B4 -> 39
A5: 120W Cordless Vacuum Cleaners Handheld Electric Vacuum Cleaner | B5: 69 | E5: =A5 -> 120W Cordless Vacuum Cleaners Handheld Electric Vacuum Cleaner | F5: =B5 -> 69
A6: 137 Pieces Cake Decorating Tool Set Baking Supplies | B6: 55 | E6: =A6 -> 137 Pieces Cake Decorating Tool Set Baking Supplies | F6: =B6 -> 55
A7: 3D Waterproof EVA Plastic Shower Curtain 1.8*2Mtrs | B7: 44 | E7: =A7 -> 3D Waterproof EVA Plastic Shower Curtain 1.8*2Mtrs | F7: =B7 -> 44
A8: 53 Pieces/Set Yarn Knitting Crochet Hooks With Bag - Pansies | B8: 32 | E8: =A8 -> 53 Pieces/Set Yarn Knitting Crochet Hooks With Bag - Pansies | F8: =B8 -> 32
A9: Electronic Digital Display Vernier Caliper | B9: 49 | E9: =A9 -> Electronic Digital Display Vernier Caliper | F9: =B9 -> 49
A10: Punch-free Great Load Bearing Bathroom Storage Rack Wall Shelf-White | B10: 36 | E10: =A10 -> Punch-free Great Load Bearing Bathroom Storage Rack Wall Shelf-White | F10: =B10 -> 36
A11: Grand Total | B11: 324 | E11: =A11 -> Grand Total | F11: =B11 -> 324
A12: Products | B12: No of Review | C12: Rated
A13: 100 Pcs Crochet Hook Tool Set Knitting Hook Set With Box | B13: 39 | C13: 4.7
A14: 120W Cordless Vacuum Cleaners Handheld Electric Vacuum Cleaner | B14: 69 | C14: 2.8
A15: 137 Pieces Cake Decorating Tool Set Baking Supplies | B15: 55 | C15: 4.6
A16: 3D Waterproof EVA Plastic Shower Curtain 1.8*2Mtrs | B16: 44 | C16: 4.6
A17: Electronic Digital Display Vernier Caliper | B17: 49 | C17: 4.6
A18: Grand Total | B18: 256 | C18: 21.3

Sheet Sheet11
A1: Discount | B1: (Multiple Items)
A3: Row Labels | B3: Product of Discount
A4: 5-PCS Stainless Steel Cooking Pot Set With Steamed Slices | B4: 0.55 | D4: =A4 -> 5-PCS Stainless Steel Cooking Pot Set With Steamed Slices | E4: =B4 -> 0.55
A5: 6 In 1 Bottle Can Opener Multifunctional Easy Opener | B5: 0.64 | D5: =A5 -> 6 In 1 Bottle Can Opener Multifunctional Easy Opener | E5: =B5 -> 0.64
A6: Creative Owl Shape Keychain Black | B6: 0.61 | D6: =A6 -> Creative Owl Shape Keychain Black | E6: =B6 -> 0.61
A7: LASA 3 Tier Bamboo Shoe Bench Storage Shelf | B7: 0.54 | D7: =A7 -> LASA 3 Tier Bamboo Shoe Bench Storage Shelf | E7: =B7 -> 0.54
A8: LASA FOLDING TABLE SERVING STAND | B8: 0.55 | D8: =A8 -> LASA FOLDING TABLE SERVING STAND | E8: =B8 -> 0.55
A9: Mythco 120COB Solar Wall Ligt With Motion Sensor And Remote Control 3 Modes | B9: 0.54 | D9: =A9 -> Mythco 120COB Solar Wall Ligt With Motion Sensor And Remote Control 3 Modes | E9: =B9 -> 0.54
A10: Simple Metal Dog Art Sculpture Decoration For Home Office | B10: 0.55 | D10: =A10 -> Simple Metal Dog Art Sculpture Decoration For Home Office | E10: =B10 -> 0.55
A11: Grand Total | B11: 0.018940236 | D11: =A11 -> Grand Total | E11: =1 -> 1
A13: Discount | B13: (Multiple Items)
A15: Row Labels | B15: Product of Discount
A16: 5-PCS Stainless Steel Cooking Pot Set With Steamed Slices | B16: 0.55
A17: 6 In 1 Bottle Can Opener Multifunctional Easy Opener | B17: 0.64
A18: Creative Owl Shape Keychain Black | B18: 0.61
A19: LASA 3 Tier Bamboo Shoe Bench Storage Shelf | B19: 0.54
A20: LASA FOLDING TABLE SERVING STAND | B20: 0.55
A21: Mythco 120COB Solar Wall Ligt With Motion Sensor And Remote Control 3 Modes | B21: 0.54
A22: Simple Metal Dog Art Sculpture Decoration For Home Office | B22: 0.55
A23: Grand Total | B23: 0.018940236

Sheet Sheet12
A3: Row Labels | B3: Sum of Review
A4: 0.01
A5: 0.02
A6: 0.03
A7: 0.04
A8: 0.08
A9: 0.09 | B9: 15
A10: 0.11
A11: 0.13 | B11: 6
A12: 0.14
A13: 0.18 | B13: 12
A14: 0.19 | B14: 5
A15: 0.2 | B15: 12
A16: 0.21 | B16: 1
A17: 0.22 | B17: 16
A18: 0.23 | B18: 14
A19: 0.24 | B19: 55
A20: 0.25 | B20: 24
A21: 0.26 | B21: 5
A22: 0.27 | B22: 52
A23: 0.29 | B23: 5
A24: 0.3 | B24: 20
... A28: 0.35 | B28: 55
A29: 0.36
A30: 0.37 | B30: 9
A31: 0.38 | B31: 4
A32: 0.39 | B32: 5
A33: 0.4 | B33: 1
A34: 0.41 | B34: 36
A35: 0.42 | B35: 6
A36: 0.43 | B36: 11
A37: 0.45 | B37: 28
A38: 0.46 | B38: 3
A39: 0.47 | B39: 39
A40: 0.48 | B40: 9
A41: 0.49 | B41: 118
... A47: 0.55 | B47: 18
A48: 0.61
A49: 0.64
A50: Grand Total | B50: 723

Sheet Sheet13
A1: Review | B1: (Multiple Items)
A3: Rating Score | B3: No of Reviews
A4: 2 | B4: 1
A5: 2.1 | B5: 20
A6: 2.2 | B6: 12
A7: 2.3 | B7: 13
A8: 2.5 | B8: 6
A9: 2.6 | B9: 17
A10: 2.7 | B10: 15
A11: 2.8 | B11: 69
A12: 2.9 | B12: 16
A13: 3 | B13: 26
A14: 3.3 | B14: 13
A15: 3.8 | B15: 30
... A25: 5 | B25: 12
A26: Grand Total | B26: 723

Sheet Sheet14
A3: Row Labels | B3: Count of Product
A4: Average Rating | B4: 22
A5: Excellent Rating | B5: 23
A6: Poor rating | B6: 12
A7: Unknown | B7: 55
A8: Grand Total | B8: 112

Sheet Sheet17
A3: Count of Product | B3: Column Labels
A4: Row Labels | B4: Average Rating | C4: Excellent Rating | D4: Poor rating | E4: Unknown | F4: Grand Total
A5: High Discount | B5: 11 | C5: 9 | D5: 10 | E5: 32 | F5: 62
A6: Low Discount | B6: 2 | C6: 1 | D6: 1 | E6: 14 | F6: 18
A7: Medium Discount | B7: 9 | C7: 13 | D7: 1 | E7: 9 | F7: 32
A8: Grand Total | B8: 22 | C8: 23 | D8: 12 | E8: 55 | F8: 112

Sheet Excel_jumia
A1: Product | B1: Current price | C1: old price | D1: Discount Amount | E1: Discount | F1: Review | G1: Rating | H1: Rating category | I1: Discount category
A2: 115 Piece Set Of Multifunctional Precision Screwdrivers | B2: 950 | C2: 1525 | D2: =C2-B2 -> 575 | E2: 0.38 | F2: 2 | G2: 4.5 | H2: {=_xlfn.IFS(G2="","Unknown",G2<3,"Poor rating",G2<=4.4,"Average Rating",G2>4.4,"Excellent Rating")} -> Excellent Rating | I2: {=_xlfn.IFS(E2<20%,"Low Discount",E2<=40%,"Medium Discount",E2>40%,"High Discount")} -> Medium Discount
A3: Metal Decorative Hooks Key Hangers Entryway Wall Hooks Towel Hooks - Home | B3: 527 | C3: 999 | D3: =C3-B3 -> 472 | E3: 0.47 | F3: 14 | G3: 4.1 | H3: {=_xlfn.IFS(G3="","Unknown",G3<3,"Poor rating",G3<=4.4,"Average Rating",G3>4.4,"Excellent Rating")} -> Average Rating | I3: {=_xlfn.IFS(E3<20%,"Low Discount",E3<=40%,"Medium Discount",E3>40%,"High Discount")} -> High Discount
A4: Portable Mini Cordless Car Vacuum Cleaner - Blue | B4: 2199 | C4: 2923 | D4: =C4-B4 -> 724 | E4: 0.25 | F4: 24 | G4: 4.6 | H4: {=_xlfn.IFS(G4="","Unknown",G4<3,"Poor rating",G4<=4.4,"Average Rating",G4>4.4,"Excellent Rating")} -> Excellent Rating | I4: {=_xlfn.IFS(E4<20%,"Low Discount",E4<=40%,"Medium Discount",E4>40%,"High Discount")} -> Medium Discount
A5: Weighing Scale Digital Bathroom Body Fat Scale USB-Black | B5: 1580 | C5: 2499 | D5: =C5-B5 -> 919 | E5: 0.37 | F5: 7 | G5: 4.7 | H5: {=_xlfn.IFS(G5="","Unknown",G5<3,"Poor rating",G5<=4.4,"Average Rating",G5>4.4,"Excellent Rating")} -> Excellent Rating | I5: {=_xlfn.IFS(E5<20%,"Low Discount",E5<=40%,"Medium Discount",E5>40%,"High Discount")} -> Medium Discount
A6: Portable Home Small Air Humidifier 3-Speed Fan - Green | B6: 1740 | C6: 2356 | D6: =C6-B6 -> 616 | E6: 0.26 | F6: 5 | G6: 4.8 | H6: {=_xlfn.IFS(G6="","Unknown",G6<3,"Poor rating",G6<=4.4,"Average Rating",G6>4.4,"Excellent Rating")} -> Excellent Rating | I6: {=_xlfn.IFS(E6<20%,"Low Discount",E6<=40%,"Medium Discount",E6>40%,"High Discount")} -> Medium Discount
A7: 220V 60W Electric Soldering Iron Kits With Tools, Tips, And Multimeter | B7: 2999 | C7: 3290 | D7: =C7-B7 -> 291 | E7: 0.09 | F7: 15 | G7: 4 | H7: {=_xlfn.IFS(G7="","Unknown",G7<3,"Poor rating",G7<=4.4,"Average Rating",G7>4.4,"Excellent Rating")} -> Average Rating | I7: {=_xlfn.IFS(E7<20%,"Low Discount",E7<=40%,"Medium Discount",E7>40%,"High Discount")} -> Low Discount
A8: 137 Pieces Cake Decorating Tool Set Baking Supplies | B8: 2319 | C8: 3032 | D8: =C8-B8 -> 713 | E8: 0.24 | F8: 55 | G8: 4.6 | H8: {=_xlfn.IFS(G8="","Unknown",G8<3,"Poor rating",G8<=4.4,"Average Rating",G8>4.4,"Excellent Rating")} -> Excellent Rating | I8: {=_xlfn.IFS(E8<20%,"Low Discount",E8<=40%,"Medium Discount",E8>40%,"High Discount")} -> Medium Discount
A9: Desk Foldable Fan Adjustable Fan Strong Wind 3 Gear Usb | B9: 988 | C9: 1580 | D9: =C9-B9 -> 592 | E9: 0.37 | F9: 2 | G9: 4 | H9: {=_xlfn.IFS(G9="","Unknown",G9<3,"Poor rating",G9<=4.4,"Average Rating",G9>4.4,"Excellent Rating")} -> Average Rating | I9: {=_xlfn.IFS(E9<20%,"Low Discount",E9<=40%,"Medium Discount",E9>40%,"High Discount")} -> Medium Discount
A10: LASA FOLDING TABLE SERVING STAND | B10: 1274 | C10: 2800 | D10: =C10-B10 -> 1526 | E10: 0.55 | F10: 5 | G10: 4.8 | H10: {=_xlfn.IFS(G10="","Unknown",G10<3,"Poor rating",G10<=4.4,"Average Rating",G10>4.4,"Excellent Rating")} -> Excellent Rating | I10: {=_xlfn.IFS(E10<20%,"Low Discount",E10<=40%,"Medium Discount",E10>40%,"High Discount")} -> High Discount
A11: 13 In 1 Home Repair Tools Box Kit Set | B11: 1600 | C11: 2929 | D11: =C11-B11 -> 1329 | E11: 0.45 | F11: 5 | G11: 3.8 | H11: {=_xlfn.IFS(G11="","Unknown",G11<3,"Poor rating",G11<=4.4,"Average Rating",G11>4.4,"Excellent Rating")} -> Average Rating | I11: {=_xlfn.IFS(E11<20%,"Low Discount",E11<=40%,"Medium Discount",E11>40%,"High Discount")} -> High Discount
A12: Genebre 115 In 1 Screwdriver Repairing Tool Set For IPhone Cellphone Hand Tool | B12: 799 | C12: 999 | D12: =C12-B12 -> 200 | E12: 0.2 | F12: 12 | G12: 4.1 | H12: {=_xlfn.IFS(G12="","Unknown",G12<3,"Poor rating",G12<=4.4,"Average Rating",G12>4.4,"Excellent Rating")} -> Average Rating | I12: {=_xlfn.IFS(E12<20%,"Low Discount",E12<=40%,"Medium Discount",E12>40%,"High Discount")} -> Medium Discount
A13: 100 Pcs Crochet Hook Tool Set Knitting Hook Set With Box | B13: 990 | C13: 1500 | D13: =C13-B13 -> 510 | E13: 0.34 | F13: 39 | G13: 4.7 | H13: {=_xlfn.IFS(G13="","Unknown",G13<3,"Poor rating",G13<=4.4,"Average Rating",G13>4.4,"Excellent Rating")} -> Excellent Rating | I13: {=_xlfn.IFS(E13<20%,"Low Discount",E13<=40%,"Medium Discount",E13>40%,"High Discount")} -> Medium Discount
... A22: 3PCS Single Head Knitting Crochet Sweater Needle Set | B22: 38 | C22: 80 | D22: =C22-B22 -> 42 | E22: 0.53 | F22: 13 | G22: 3.3 | H22: {=_xlfn.IFS(G22="","Unknown",G22<3,"Poor rating",G22<=4.4,"Average Rating",G22>4.4,"Excellent Rating")} -> Average Rating | I22: {=_xlfn.IFS(E22<20%,"Low Discount",E22<=40%,"Medium Discount",E22>40%,"High Discount")} -> High Discount
A23: 4pcs Bathroom/Kitchen Towel Rack,Roll Paper Holder,Towel Bars,Hook | B23: 1860 | C23: 3220 | D23: =C23-B23 -> 1360 | E23: 0.42 | H23: {=_xlfn.IFS(G23="","Unknown",G23<3,"Poor rating",G23<=4.4,"Average Rating",G23>4.4,"Excellent Rating")} -> Unknown | I23: {=_xlfn.IFS(E23<20%,"Low Discount",E23<=40%,"Medium Discount",E23>40%,"High Discount")} -> High Discount
A24: LED Romantic Spaceship Starry Sky Projector,Children's Bedroom Night Light-Blue | B24: 880 | C24: 1350 | D24: =C24-B24 -> 470 | E24: 0.35 | F24: 6 | G24: 4 | H24: {=_xlfn.IFS(G24="","Unknown",G24<3,"Poor rating",G24<=4.4,"Average Rating",G24>4.4,"Excellent Rating")} -> Average Rating | I24: {=_xlfn.IFS(E24<20%,"Low Discount",E24<=40%,"Medium Discount",E24>40%,"High Discount")} -> Medium Discount
A25: Foldable Overbed Table/Desk | B25: 1650 | C25: 2150 | D25: =C25-B25 -> 500 | E25: 0.23 | F25: 14 | G25: 4.4 | H25: {=_xlfn.IFS(G25="","Unknown",G25<3,"Poor rating",G25<=4.4,"Average Rating",G25>4.4,"Excellent Rating")} -> Average Rating | I25: {=_xlfn.IFS(E25<20%,"Low Discount",E25<=40%,"Medium Discount",E25>40%,"High Discount")} -> Medium Discount
A26: LASA 3 Tier Bamboo Shoe Bench Storage Shelf | B26: 2048 | C26: 4500 | D26: =C26-B26 -> 2452 | E26: 0.54 | F26: 7 | G26: 4.3 | H26: {=_xlfn.IFS(G26="","Unknown",G26<3,"Poor rating",G26<=4.4,"Average Rating",G26>4.4,"Excellent Rating")} -> Average Rating | I26: {=_xlfn.IFS(E26<20%,"Low Discount",E26<=40%,"Medium Discount",E26>40%,"High Discount")} -> High Discount
A27: Electronic Digital Display Vernier Caliper | B27: 420 | C27: 647 | D27: =C27-B27 -> 227 | E27: 0.35 | F27: 49 | G27: 4.6 | H27: {=_xlfn.IFS(G27="","Unknown",G27<3,"Poor rating",G27<=4.4,"Average Rating",G27>4.4,"Excellent Rating")} -> Excellent Rating | I27: {=_xlfn.IFS(E27<20%,"Low Discount",E27<=40%,"Medium Discount",E27>40%,"High Discount")} -> Medium Discount
A28: Portable Wardrobe Nonwoven With 3 Hanging Rods And 6 Storage Shelves | B28: 2880 | C28: 3520 | D28: =C28-B28 -> 640 | E28: 0.18 | F28: 12 | G28: 3.8 | H28: {=_xlfn.IFS(G28="","Unknown",G28<3,"Poor rating",G28<=4.4,"Average Rating",G28>4.4,"Excellent Rating")} -> Average Rating | I28: {=_xlfn.IFS(E28<20%,"Low Discount",E28<=40%,"Medium Discount",E28>40%,"High Discount")} -> Low Discount
A29: 12 Litre Black Insulated Lunch Box | B29: 1350 | C29: 1990 | D29: =C29-B29 -> 640 | E29: 0.32 | F29: 13 | G29: 3.8 | H29: {=_xlfn.IFS(G29="","Unknown",G29<3,"Poor rating",G29<=4.4,"Average Rating",G29>4.4,"Excellent Rating")} -> Average Rating | I29: {=_xlfn.IFS(E29<20%,"Low Discount",E29<=40%,"Medium Discount",E29>40%,"High Discount")} -> Medium Discount
A30: 52 Pieces Cake Decorating Tool Set Gift Kit Baking Supplies | B30: 1758 | C30: 2499 | D30: =C30-B30 -> 741 | E30: 0.3 | F30: 20 | G30: 4.1 | H30: {=_xlfn.IFS(G30="","Unknown",G30<3,"Poor rating",G30<=4.4,"Average Rating",G30>4.4,"Excellent Rating")} -> Average Rating | I30: {=_xlfn.IFS(E30<20%,"Low Discount",E30<=40%,"Medium Discount",E30>40%,"High Discount")} -> Medium Discount
A31: MultiFunctional Storage Rack Multi-layer Bookshelf | B31: 2200 | C31: 4080 | D31: =C31-B31 -> 1880 | E31: 0.46 | H31: {=_xlfn.IFS(G31="","Unknown",G31<3,"Poor rating",G31<=4.4,"Average Rating",G31>4.4,"Excellent Rating")} -> Unknown | I31: {=_xlfn.IFS(E31<20%,"Low Discount",E31<=40%,"Medium Discount",E31>40%,"High Discount")} -> High Discount
A32: Exfoliate And Exfoliate Face Towel - Black | B32: 185 | C32: 382 | D32: =C32-B32 -> 197 | E32: 0.52 | F32: 9 | G32: 4.3 | H32: {=_xlfn.IFS(G32="","Unknown",G32<3,"Poor rating",G32<=4.4,"Average Rating",G32>4.4,"Excellent Rating")} -> Average Rating | I32: {=_xlfn.IFS(E32<20%,"Low Discount",E32<=40%,"Medium Discount",E32>40%,"High Discount")} -> High Discount
A33: 12 Litre Insulated Lunch Box Grey | B33: 980 | C33: 1490 | D33: =C33-B33 -> 510 | E33: 0.34 | F33: 12 | G33: 4.7 | H33: {=_xlfn.IFS(G33="","Unknown",G33<3,"Poor rating",G33<=4.4,"Average Rating",G33>4.4,"Excellent Rating")} -> Excellent Rating | I33: {=_xlfn.IFS(E33<20%,"Low Discount",E33<=40%,"Medium Discount",E33>40%,"High Discount")} -> Medium Discount
A34: LED Eye Protection Desk Lamp , Study, Reading, USB Fan - Double Pen Holder | B34: 1820 | C34: 3490 | D34: =C34-B34 -> 1670 | E34: 0.48 | F34: 9 | G34: 4.3 | H34: {=_xlfn.IFS(G34="","Unknown",G34<3,"Poor rating",G34<=4.4,"Average Rating",G34>4.4,"Excellent Rating")} -> Average Rating | I34: {=_xlfn.IFS(E34<20%,"Low Discount",E34<=40%,"Medium Discount",E34>40%,"High Discount")} -> High Discount
A35: 53Pcs/Set Yarn Knitting Crochet Hooks With Bag - Fortune Cat | B35: 1940 | C35: 2650 | D35: =C35-B35 -> 710 | E35: 0.27 | F35: 20 | G35: 4.7 | H35: {=_xlfn.IFS(G35="","Unknown",G35<3,"Poor rating",G35<=4.4,"Average Rating",G35>4.4,"Excellent Rating")} -> Excellent Rating | I35: {=_xlfn.IFS(E35<20%,"Low Discount",E35<=40%,"Medium Discount",E35>40%,"High Discount")} -> Medium Discount
A36: 53 Pieces/Set Yarn Knitting Crochet Hooks With Bag - Pansies | B36: 1980 | C36: 2699 | D36: =C36-B36 -> 719 | E36: 0.27 | F36: 32 | G36: 4.5 | H36: {=_xlfn.IFS(G36="","Unknown",G36<3,"Poor rating",G36<=4.4,"Average Rating",G36>4.4,"Excellent Rating")} -> Excellent Rating | I36: {=_xlfn.IFS(E36<20%,"Low Discount",E36<=40%,"Medium Discount",E36>40%,"High Discount")} -> Medium Discount
A37: DIY File Folder, Office Drawer File Holder, Pen Holder, Desktop Storage Rack | B37: 1620 | C37: 2690 | D37: =C37-B37 -> 1070 | E37: 0.4 | F37: 1 | G37: 5 | H37: {=_xlfn.IFS(G37="","Unknown",G37<3,"Poor rating",G37<=4.4,"Average Rating",G37>4.4,"Excellent Rating")} -> Excellent Rating | I37: {=_xlfn.IFS(E37<20%,"Low Discount",E37<=40%,"Medium Discount",E37>40%,"High Discount")} -> Medium Discount
A38: Classic Black Cat Cotton Hemp Pillow Case For Home Car | B38: 171 | C38: 360 | D38: =C38-B38 -> 189 | E38: 0.53 | F38: 2 | G38: 5 | H38: {=_xlfn.IFS(G38="","Unknown",G38<3,"Poor rating",G38<=4.4,"Average Rating",G38>4.4,"Excellent Rating")} -> Excellent Rating | I38: {=_xlfn.IFS(E38<20%,"Low Discount",E38<=40%,"Medium Discount",E38>40%,"High Discount")} -> High Discount
A39: Punch-free Great Load Bearing Bathroom Storage Rack Wall Shelf-White | B39: 389 | C39: 656 | D39: =C39-B39 -> 267 | E39: 0.41 | F39: 36 | G39: 4.3 | H39: {=_xlfn.IFS(G39="","Unknown",G39<3,"Poor rating",G39<=4.4,"Average Rating",G39>4.4,"Excellent Rating")} -> Average Rating | I39: {=_xlfn.IFS(E39<20%,"Low Discount",E39<=40%,"Medium Discount",E39>40%,"High Discount")} -> High Discount
A40: 1/2/3 Seater Elastic Sofa Cover,Living Room/Home Decor Chair Cover-Grey | B40: =(1620 +1980)/2 -> 1800 | C40: =(2200+3200)/2 -> 2700 | D40: =C40-B40 -> 900 | E40: 0.38 | F40: 2 | G40: 4.5 | H40: {=_xlfn.IFS(G40="","Unknown",G40<3,"Poor rating",G40<=4.4,"Average Rating",G40>4.4,"Excellent Rating")} -> Excellent Rating | I40: {=_xlfn.IFS(E40<20%,"Low Discount",E40<=40%,"Medium Discount",E40>40%,"High Discount")} -> Medium Discount
A41: LASA Stainless Steel Double Wall Mount Soap Dispenser - 500ml | B41: 2750 | C41: 4471 | D41: =C41-B41 -> 1721 | E41: 0.38 | H41: {=_xlfn.IFS(G41="","Unknown",G41<3,"Poor rating",G41<=4.4,"Average Rating",G41>4.4,"Excellent Rating")} -> Unknown | I41: {=_xlfn.IFS(E41<20%,"Low Discount",E41<=40%,"Medium Discount",E41>40%,"High Discount")} -> Medium Discount
A42: 4M Float Switch Water Level Controller -Water Tank | B42: 475 | C42: 931 | D42: =C42-B42 -> 456 | E42: 0.49 | H42: {=_xlfn.IFS(G42="","Unknown",G42<3,"Poor rating",G42<=4.4,"Average Rating",G42>4.4,"Excellent Rating")} -> Unknown | I42: {=_xlfn.IFS(E42<20%,"Low Discount",E42<=40%,"Medium Discount",E42>40%,"High Discount")} -> High Discount
A43: Modern Sofa Throw Pillow Cover-45x45cm-Blue&Red | B43: 238 | C43: 476 | D43: =C43-B43 -> 238 | E43: 0.5 | H43: {=_xlfn.IFS(G43="","Unknown",G43<3,"Poor rating",G43<=4.4,"Average Rating",G43>4.4,"Excellent Rating")} -> Unknown | I43: {=_xlfn.IFS(E43<20%,"Low Discount",E43<=40%,"Medium Discount",E43>40%,"High Discount")} -> High Discount
A44: Shower Cap Wide Elastic Band Cover Reusable Bashroom Cap | B44: 2132 | C44: 2169 | D44: =C44-B44 -> 37 | E44: 0.02 | H44: {=_xlfn.IFS(G44="","Unknown",G44<3,"Poor rating",G44<=4.4,"Average Rating",G44>4.4,"Excellent Rating")} -> Unknown | I44: {=_xlfn.IFS(E44<20%,"Low Discount",E44<=40%,"Medium Discount",E44>40%,"High Discount")} -> Low Discount
A45: Christmas Elk Fence Yard Lawn Decorations Cute For Holidays | B45: 999 | C45: 2000 | D45: =C45-B45 -> 1001 | E45: 0.5 | H45: {=_xlfn.IFS(G45="","Unknown",G45<3,"Poor rating",G45<=4.4,"Average Rating",G45>4.4,"Excellent Rating")} -> Unknown | I45: {=_xlfn.IFS(E45<20%,"Low Discount",E45<=40%,"Medium Discount",E45>40%,"High Discount")} -> High Discount
A46: 60W Hot Melt Glue Sprayer - Efficient And Stable Glue Dispensing | B46: 1190 | C46: 1785 | D46: =C46-B46 -> 595 | E46: 0.33 | H46: {=_xlfn.IFS(G46="","Unknown",G46<3,"Poor rating",G46<=4.4,"Average Rating",G46>4.4,"Excellent Rating")} -> Unknown | I46: {=_xlfn.IFS(E46<20%,"Low Discount",E46<=40%,"Medium Discount",E46>40%,"High Discount")} -> Medium Discount
A47: Car Phone Charging Stand | B47: 671 | C47: 1316 | D47: =C47-B47 -> 645 | E47: 0.49 | H47: {=_xlfn.IFS(G47="","Unknown",G47<3,"Poor rating",G47<=4.4,"Average Rating",G47>4.4,"Excellent Rating")} -> Unknown | I47: {=_xlfn.IFS(E47<20%,"Low Discount",E47<=40%,"Medium Discount",E47>40%,"High Discount")} -> High Discount
A48: 2pcs Solar Street Light Flood Light Outdoor | B48: 1200 | C48: 1950 | D48: =C48-B48 -> 750 | E48: 0.38 | H48: {=_xlfn.IFS(G48="","Unknown",G48<3,"Poor rating",G48<=4.4,"Average Rating",G48>4.4,"Excellent Rating")} -> Unknown | I48: {=_xlfn.IFS(E48<20%,"Low Discount",E48<=40%,"Medium Discount",E48>40%,"High Discount")} -> Medium Discount
...

Sheet Data Analysis
A1: Average | B1: Value
A2: Current Price | B2: =AVERAGE(Excel_jumia!B2:B113) -> 1186.8929
A3: Old Price | B3: =AVERAGE(Excel_jumia!C2:C113) -> 1811.1071
A4: Discount % | B4: =AVERAGE(Excel_jumia!E2:E113) -> 0.36776786
A5: Rating | B5: =AVERAGE(Excel_jumia!G2:G113) -> 3.8894737
A8: Most Expensive and Least Expensive Product
A9: Most Expensive | B9: =MAX(Excel_jumia!B2:B113) -> 3750 | C9: 32PCS Portable Cordless Drill Set With Cyclic Battery Drive -26 Variable Speed
A10: Least Expensive | B10: =MIN(Excel_jumia!B2:B113) -> 38 | C10: 3PCS Single Head Knitting Crochet Sweater Needle Set
A12: AVG By Discount Category
B13: Average Rating | C13: Average Discount
A14: Low Discount | B14: =AVERAGEIF(Excel_jumia!I2:I113, "Low Discount", Excel_jumia!G2:G113) -> 3.725 | C14: =AVERAGEIF(Excel_jumia!I2:I113, "Low Discount", Excel_jumia!E2:E113) -> 0.072222222
A15: Medium Discount | B15: =AVERAGEIF(Excel_jumia!I2:I113, "Medium Discount", Excel_jumia!G2:G113) -> 4.2782609 | C15: =AVERAGEIF(Excel_jumia!I3:I114, "Medium Discount", Excel_jumia!E3:E114) -> 0.30774194
A16: High Discount | B16: =AVERAGEIF(Excel_jumia!I2:I113, "High Discount", Excel_jumia!G2:G113) -> 3.6133333 | C16: =AVERAGEIF(Excel_jumia!I4:I115, "High Discount", Excel_jumia!E4:E115) -> 0.48360656
A18: Distribution According to Rating Categories
A19: Poor rating | B19: =COUNTIF(Excel_jumia!H2:H113, "Poor Rating") -> 12
A20: Excellent rating | B20: =COUNTIF(Excel_jumia!H2:H113, "Excellent Rating") -> 23
A21: Average rating | B21: =COUNTIF(Excel_jumia!H2:H114, "Average Rating") -> 22

Sheet Trend Analysis
A18: 1. High discounts on a product do not necessarily guarantee higher customer ratings.
A20: 2. A high product rating does not necessarily result in an increased number of customer reviews.

Sheet Product performance
A1: Top 10 Products with the highest discounts
A2: Product | B2: Current price | C2: old price | D2: Discount Amount | E2: Discount | F2: Review | G2: Rating | H2: Rating category | I2: Discount category
A3: LASA FOLDING TABLE SERVING STAND | B3: 1274 | C3: 2800 | D3: 1526 | E3: 0.55 | F3: 5 | G3: 4.8 | H3: Excellent Rating | I3: High Discount
A4: 3PCS Single Head Knitting Crochet Sweater Needle Set | B4: 38 | C4: 80 | D4: 42 | E4: 0.53 | F4: 13 | G4: 3.3 | H4: Average Rating | I4: High Discount
A5: LASA 3 Tier Bamboo Shoe Bench Storage Shelf | B5: 2048 | C5: 4500 | D5: 2452 | E5: 0.54 | F5: 7 | G5: 4.3 | H5: Average Rating | I5: High Discount
A6: Exfoliate And Exfoliate Face Towel - Black | B6: 185 | C6: 382 | D6: 197 | E6: 0.52 | F6: 9 | G6: 4.3 | H6: Average Rating | I6: High Discount
A7: Classic Black Cat Cotton Hemp Pillow Case For Home Car | B7: 171 | C7: 360 | D7: 189 | E7: 0.53 | F7: 2 | G7: 5 | H7: Excellent Rating | I7: High Discount
A8: Creative Owl Shape Keychain Black | B8: 199 | C8: 504 | D8: 305 | E8: 0.61 | H8: Unknown | I8: High Discount
A9: Simple Metal Dog Art Sculpture Decoration For Home Office | B9: 399 | C9: 896 | D9: 497 | E9: 0.55 | H9: Unknown | I9: High Discount
A10: Mythco 120COB Solar Wall Ligt With Motion Sensor And Remote Control 3 Modes | B10: 458 | C10: 986 | D10: 528 | E10: 0.54 | F10: 10 | G10: 3 | H10: Average Rating | I10: High Discount
A11: 5-PCS Stainless Steel Cooking Pot Set With Steamed Slices | B11: 2115 | C11: 4700 | D11: 2585 | E11: 0.55 | F11: 13 | G11: 2.1 | H11: Poor rating | I11: High Discount
A12: Intelligent LED Body Sensor Wireless Lighting Night Light USB | B12: 325 | C12: 680 | D12: 355 | E12: 0.52 | F12: 15 | G12: 2.7 | H12: Poor rating | I12: High Discount
A13: 6 In 1 Bottle Can Opener Multifunctional Easy Opener | B13: 199 | C13: 553 | D13: 354 | E13: 0.64 | H13: Unknown | I13: High Discount
A14: Top 10 Products with the highest reviews
A15: Product | B15: Current price | C15: old price | D15: Discount Amount | E15: Discount | F15: Review | G15: Rating | H15: Rating category | I15: Discount category
A16: 120W Cordless Vacuum Cleaners Handheld Electric Vacuum Cleaner | B16: 445 | C16: 873 | D16: 428 | E16: 0.49 | F16: 69 | G16: 2.8 | H16: Poor rating | I16: High Discount
A17: 137 Pieces Cake Decorating Tool Set Baking Supplies | B17: 2319 | C17: 3032 | D17: 713 | E17: 0.24 | F17: 55 | G17: 4.6 | H17: Excellent Rating | I17: Medium Discount
A18: Electronic Digital Display Vernier Caliper | B18: 420 | C18: 647 | D18: 227 | E18: 0.35 | F18: 49 | G18: 4.6 | H18: Excellent Rating | I18: Medium Discount
A19: 3D Waterproof EVA Plastic Shower Curtain 1.8*2Mtrs | B19: 998 | C19: 1966 | D19: 968 | E19: 0.49 | F19: 44 | G19: 4.6 | H19: Excellent Rating | I19: High Discount
A20: 100 Pcs Crochet Hook Tool Set Knitting Hook Set With Box | B20: 990 | C20: 1500 | D20: 510 | E20: 0.34 | F20: 39 | G20: 4.7 | H20: Excellent Rating | I20: Medium Discount
A21: Punch-free Great Load Bearing Bathroom Storage Rack Wall Shelf-White | B21: 389 | C21: 656 | D21: 267 | E21: 0.41 | F21: 36 | G21: 4.3 | H21: Average Rating | I21: High Discount
A22: 53 Pieces/Set Yarn Knitting Crochet Hooks With Bag - Pansies | B22: 1980 | C22: 2699 | D22: 719 | E22: 0.27 | F22: 32 | G22: 4.5 | H22: Excellent Rating | I22: Medium Discount
A23: Portable Mini Cordless Car Vacuum Cleaner - Blue | B23: 2199 | C23: 2923 | D23: 724 | E23: 0.25 | F23: 24 | G23: 4.6 | H23: Excellent Rating | I23: Medium Discount
A24: 52 Pieces Cake Decorating Tool Set Gift Kit Baking Supplies | B24: 1758 | C24: 2499 | D24: 741 | E24: 0.3 | F24: 20 | G24: 4.1 | H24: Average Rating | I24: Medium Discount
A25: 53Pcs/Set Yarn Knitting Crochet Hooks With Bag - Fortune Cat | B25: 1940 | C25: 2650 | D25: 710 | E25: 0.27 | F25: 20 | G25: 4.7 | H25: Excellent Rating | I25: Medium Discount
A26: Agapeon Toothbrush Holder And Toothpaste Dispenser | B26: 382 | C26: 700 | D26: 318 | E26: 0.45 | F26: 17 | G26: 2.6 | H26: Poor rating | I26: High Discount
A28: Top 5 Highest rated
A29: Product | B29: Current price | C29: old price | D29: Discount Amount | E29: Discount | F29: Review | G29: Rating | H29: Rating category | I29: Discount category
A30: Portable Mini Cordless Car Vacuum Cleaner - Blue | B30: 2199 | C30: 2923 | D30: 724 | E30: 0.25 | F30: 24 | G30: 4.6 | H30: Excellent Rating | I30: Medium Discount
A31: 137 Pieces Cake Decorating Tool Set Baking Supplies | B31: 2319 | C31: 3032 | D31: 713 | E31: 0.24 | F31: 55 | G31: 4.6 | H31: Excellent Rating | I31: Medium Discount
A32: 100 Pcs Crochet Hook Tool Set Knitting Hook Set With Box | B32: 990 | C32: 1500 | D32: 510 | E32: 0.34 | F32: 39 | G32: 4.7 | H32: Excellent Rating | I32: Medium Discount
A33: 3D Waterproof EVA Plastic Shower Curtain 1.8*2Mtrs | B33: 998 | C33: 1966 | D33: 968 | E33: 0.49 | F33: 44 | G33: 4.6 | H33: Excellent Rating | I33: High Discount
A34: Electronic Digital Display Vernier Caliper | B34: 420 | C34: 647 | D34: 227 | E34: 0.35 | F34: 49 | G34: 4.6 | H34: Excellent Rating | I34: Medium Discount
A35: 53Pcs/Set Yarn Knitting Crochet Hooks With Bag - Fortune Cat | B35: 1940 | C35: 2650 | D35: 710 | E35: 0.27 | F35: 20 | G35: 4.7 | H35: Excellent Rating | I35: Medium Discount
A37: Bottom 5 Lowest rated Product
A38: Product | B38: Current price | C38: old price | D38: Discount Amount | E38: Discount | F38: Review | G38: Rating | H38: Rating category | I38: Discount category
A39: 52 Pieces Cake Decorating Tool Set Gift Kit Baking Supplies | B39: 1758 | C39: 2499 | D39: 741 | E39: 0.3 | F39: 20 | G39: 4.1 | H39: Average Rating | I39: Medium Discount
A40: 53 Pieces/Set Yarn Knitting Crochet Hooks With Bag - Pansies | B40: 1980 | C40: 2699 | D40: 719 | E40: 0.27 | F40: 32 | G40: 4.5 | H40: Excellent Rating | I40: Medium Discount
A41: Punch-free Great Load Bearing Bathroom Storage Rack Wall Shelf-White | B41: 389 | C41: 656 | D41: 267 | E41: 0.41 | F41: 36 | G41: 4.3 | H41: Average Rating | I41: High Discount
A42: 120W Cordless Vacuum Cleaners Handheld Electric Vacuum Cleaner | B42: 445 | C42: 873 | D42: 428 | E42: 0.49 | F42: 69 | G42: 2.8 | H42: Poor rating | I42: High Discount
...
